Workbook

Sheet VM and Cluster Sizing
A1: Electric Petrol DC1 - VM and Cluster Sizing Calculator
A3: INPUT PARAMETERS (change these to adjust design) | D3: PRODUCT REFERENCES
A4: Max Applications | B4: 100 | D4: Dell PowerEdge R760 Spec Sheet
A5: Max Instances per Application | B5: 10 | D5: dell.com/en-ie > PowerEdge R760
A6: VMs per Application Instance | B6: 10 | D6: Consultant Report Requirement
A7: vCPUs per VM | B7: 2 | D7: Consultant Report: 2 CPU per VM
A8: Physical Cores per Server (2x Intel Xeon Gold 6430, 32c each) | B8: 64 | C8: Dell Xeon Gold 6430 = 32 cores/socket, 2 sockets | D8: Intel Xeon Gold 6430 (TDP 270W, 2.1GHz base)
A9: vCPU Overcommit Ratio | B9: 4 | D9: Industry standard for mixed workloads
A10: Servers per Cluster | B10: 5 | D10: Consultant recommendation: 5-server clusters
A11: HA Reserved Servers per Cluster (N+1) | B11: 1
A12: RAM per Server (GB) - 16x32GB DDR5-4800 RDIMM | B12: 512 | D12: Dell R760 supports up to 32 DIMM slots, DDR5-4800
A13: Memory Overcommit Ratio | B13: 1.5
A15: CALCULATED VALUES
A16: Total Maximum VMs | B16: =B4*B5*B6 -> 10000
A17: Total vCPUs Required | B17: =B16*B7 -> 20000
A18: Usable vCPUs per Server | B18: =B8*B9 -> 256
A19: Usable Servers per Cluster | B19: =B10-B11 -> 4
A20: Usable vCPUs per Cluster | B20: =B18*B19 -> 1024
A21: VMs per Cluster | B21: =FLOOR(B20/B7,1) -> 512
A22: Clusters Required (CPU) | B22: =ROUNDUP(B16/B21,0) -> 20
A23: Total Compute Servers (CPU) | B23: =B22*B10 -> 100
A25: RAM VALIDATION
A26: RAM per VM (avg, GB) | B26: 7.2
A27: Total RAM Required (GB) | B27: =B16*B26 -> 72000
A28: Effective RAM per Cluster (GB) | B28: =B19*B12*B13 -> 3072
A29: Clusters Required (RAM) | B29: =ROUNDUP(B27/B28,0) -> 24
A30: CLUSTERS REQUIRED (max of CPU/RAM) | B30: =MAX(B22,B29) -> 24
A31: TOTAL COMPUTE SERVERS | B31: =B30*B10 -> 120
A33: PRODUCT PRICING (Ireland, EUR ex-VAT)
A34: Product | B34: Config | C34: Price (EUR) | D34: Source
A35: Dell PowerEdge R760 (2U Rack) | B35: 2x Xeon Gold 6430 (32c), 512GB DDR5, 2x480GB SSD BOSS, 6x1.92TB NVMe, 2x1400W PSU | C35: 18500 | D35: dell.com/en-ie (Configure to Order)
A36: Dell PowerEdge R660 (1U Rack) | B36: 1x Xeon Silver 4416+ (20c), 128GB DDR5, 2x960GB SSD, 2x800W PSU | C36: 7200 | D36: dell.com/en-ie (Configure to Order)
A37: Dell PowerStore 5200T | B37: All-Flash, Dual Active Controllers, 25GbE/32Gb FC, 1PB effective | C37: 145000 | D37: dell.com/en-ie (Enterprise quote)
A38: Dell PowerStore Expansion Shelf | B38: 25x 3.84TB NVMe SSD (96TB raw per shelf) | C38: 48000 | D38: dell.com/en-ie (Enterprise quote)
A39: Dell S5248F-ON Switch | B39: 48x 25GbE SFP28 + 6x 100GbE QSFP28, OS10 | C39: 11500 | D39: dell.com/en-ie (Networking)
A40: Dell N3248TE-ON Switch | B40: 48x 1GbE RJ45 + 4x 10GbE SFP+, OS10 | C40: 4800 | D40: dell.com/en-ie (Networking)
A41: Dell N1148T-ON Switch | B41: 48x 1GbE RJ45, basic L2, OS10 Lite | C41: 1950 | D41: dell.com/en-ie (Networking)
A42: Broadcom Brocade G720 FC Switch | B42: 48-port 32Gb Fibre Channel, 24 ports active | C42: 24000 | D42: broadcom.com (Enterprise FC)
A43: Broadcom Emulex LPe36002-M2 | B43: 32Gb FC Dual-Port HBA, PCIe 4.0 x8, Low Profile | C43: 850 | D43: broadcom.com (HBA)
A44: Intel Xeon Gold 6430 Processor | B44: 32-core, 2.1GHz base, 3.4GHz turbo, 270W TDP | C44: 2700 | D44: intel.com (ARK)
...

Sheet Storage Sizing
A1: Electric Petrol DC1 - Storage Sizing
A3: STORAGE INPUT PARAMETERS
A4: Deduplication Ratio | B4: 2
A5: Compression Ratio | B5: 1.5
A6: Number of Storage Arrays | B6: 2
A7: Expansion Shelves per Array | B7: 4
A8: Drives per Shelf | B8: 25
A9: Drive Capacity (TB) | B9: 3.84
A10: RAID/Overhead Factor | B10: 0.65 | C10: 65% usable after RAID and metadata
A12: PER-VM STORAGE ALLOCATION
A13: VM Role | B13: Count (max) | C13: Storage per VM (GB) | D13: Total Storage (TB)
A14: Web Server | B14: ='VM and Cluster Sizing'!B16/5 -> 2000 | C14: 50 | D14: =B14*C14/1024 -> 97.65625
A15: Code Server | B15: ='VM and Cluster Sizing'!B16/5 -> 2000 | C15: 100 | D15: =B15*C15/1024 -> 195.3125
A16: Database Server | B16: ='VM and Cluster Sizing'!B16/5 -> 2000 | C16: 150 | D16: =B16*C16/1024 -> 292.96875
A17: AAA Server | B17: ='VM and Cluster Sizing'!B16/5 -> 2000 | C17: 30 | D17: =B17*C17/1024 -> 58.59375
A18: Logging Server | B18: ='VM and Cluster Sizing'!B16/5 -> 2000 | C18: 80 | D18: =B18*C18/1024 -> 156.25
A19: TOTAL GROSS STORAGE (TB) | B19: 10000 | D19: =SUM(D14:D18) -> 800.78125
A21: STORAGE CAPACITY CALCULATIONS
A22: Raw Capacity (TB) | B22: =B6*B7*B8*B9 -> 768
A23: Usable Capacity after RAID (TB) | B23: =B22*B10 -> 499.2
A24: Effective Capacity with Dedup+Compression (TB) | B24: =B23*B4*B5 -> 1497.6
A25: Gross Storage Required (TB) | B25: =D19 -> 800.78125
A26: Storage Headroom (TB) | B26: =B24-B25 -> 696.81875
A27: Headroom % | B27: =B26/B24 -> 0.4652903
A28: SUFFICIENT? | B28: =IF(B26>0,"YES","NO - ADD MORE STORAGE") -> YES
A30: STORAGE PRODUCT SPECIFICATIONS
A31: Dell PowerStore 5200T Specifications
A32: Max Raw Capacity (per array) | B32: 2.4 PB
A33: Max Effective Capacity (4:1 data reduction) | B33: 9.6 PB
A34: Max IOPS (100% read, 8KB block) | B34: 1200000
A35: Max IOPS (70/30 read/write, 8KB) | B35: 500000
A36: Max Bandwidth (sequential read) | B36: 25 GB/s
A37: Latency (8KB random read) | B37: < 0.3 ms
A38: Drive Bays (base unit) | B38: 25x 2.5-inch NVMe/SAS
A39: Connectivity | B39: 4x 25GbE iSCSI/NVMe-oF or 4x 32Gb FC per controller
A40: Controllers | B40: Dual Active-Active (Intel Xeon, 256GB cache total)
A41: Expansion | B41: Up to 3 expansion shelves per base (25 drives each)
A42: Data Services | B42: Inline dedup, compression, thin provisioning, snapshots, replication
A43: Price (Ireland, ex-VAT) | B43: EUR 145,000 (base), EUR 48,000 per expansion shelf
A45: I/O PERFORMANCE VALIDATION (8KB Benchmark)
...

Sheet Site Replication
A1: Electric Petrol DC1 - Site Replication Sizing
A3: REPLICATION PARAMETERS
A4: Number of Remote Sites | B4: 60
A5: RODC RAM per Site (GB) | B5: 4
A6: RODC Storage per Site (GB) | B6: 50
A7: File Replica Storage per Site (GB) | B7: 500
A8: File Server RAM per Site (GB) | B8: 8
A9: WAN Bandwidth per Site (Mbps) | B9: 100
A10: AD Replication Traffic per Site (Mbps) | B10: 5
A11: DFS-R Traffic per Site (Mbps) | B11: 30
A13: CALCULATED TOTALS
A14: Total RODC VMs | B14: =B4 -> 60
A15: Total RODC RAM (GB) | B15: =B4*B5 -> 240
A16: Total RODC Storage (TB) | B16: =B4*B6/1024 -> 2.9296875
A17: Total File Replica Storage (TB) | B17: =B4*B7/1024 -> 29.296875
A18: Total File Server RAM (GB) | B18: =B4*B8 -> 480
A19: Total WAN Bandwidth (Gbps) | B19: =B4*B9/1000 -> 6
A20: Total Replication Traffic (Gbps) | B20: =B4*(B10+B11)/1000 -> 2.1
A21: Replication Cluster Servers Needed | B21: =ROUNDUP((B15+B18)/512,0) -> 2 | C21: Based on 512GB RAM/server

Sheet Bill of Materials
A1: Electric Petrol DC1 Mayo - Bill of Materials, Labour and Cost Summary
A2: Student: Rujuta (L00187595) | Date: May 2026 | Currency: EUR | VAT Rate: 23% (Irish Standard Rate)
A3: HARDWARE
A4: Category | B4: Item | C4: Qty | D4: Net Unit Cost (EUR) | E4: Net Total (EUR) | F4: VAT Rate | G4: VAT Amount (EUR) | H4: Gross Total (EUR) | I4: Warranty (Yrs) | J4: Annual Warranty Cost (EUR) | K4: 5-Year Warranty Total (EUR)
A5: Compute | B5: Dell PowerEdge R760 (2x Xeon Gold 6430, 512GB DDR5, 6x1.92TB NVMe) | C5: 120 | D5: 18500 | E5: =C5*D5 -> 2220000 | F5: 0.23 | G5: =E5*F5 -> 510600 | H5: =E5+G5 -> 2730600 | I5: 5 | J5: =E5*0.15 -> 333000 | K5: =J5*I5 -> 1665000
A6: Compute | B6: Dell PowerEdge R660 (Xeon Silver 4416+, 128GB DDR5, 2x960GB SSD) - Mgmt | C6: 4 | D6: 7200 | E6: =C6*D6 -> 28800 | F6: 0.23 | G6: =E6*F6 -> 6624 | H6: =E6+G6 -> 35424 | I6: 5 | J6: =E6*0.15 -> 4320 | K6: =J6*I6 -> 21600
A7: Storage | B7: Dell PowerStore 5200T (All-Flash, Active-Active, 1.2M IOPS) | C7: 2 | D7: 145000 | E7: =C7*D7 -> 290000 | F7: 0.23 | G7: =E7*F7 -> 66700 | H7: =E7+G7 -> 356700 | I7: 5 | J7: =E7*0.18 -> 52200 | K7: =J7*I7 -> 261000
A8: Storage | B8: PowerStore NVMe Expansion Shelf (25x 3.84TB NVMe SSD) | C8: 8 | D8: 48000 | E8: =C8*D8 -> 384000 | F8: 0.23 | G8: =E8*F8 -> 88320 | H8: =E8+G8 -> 472320 | I8: 5 | J8: =E8*0.18 -> 69120 | K8: =J8*I8 -> 345600
A9: Network | B9: Dell S5248F-ON (48x 25GbE SFP28 + 6x 100GbE QSFP28) - Spine/Leaf | C9: 18 | D9: 11500 | E9: =C9*D9 -> 207000 | F9: 0.23 | G9: =E9*F9 -> 47610 | H9: =E9+G9 -> 254610 | I9: 5 | J9: =E9*0.12 -> 24840 | K9: =J9*I9 -> 124200
A10: Network | B10: Dell N3248TE-ON (48x 1GbE + 4x 10GbE SFP+) - WAN/Border | C10: 2 | D10: 4800 | E10: =C10*D10 -> 9600 | F10: 0.23 | G10: =E10*F10 -> 2208 | H10: =E10+G10 -> 11808 | I10: 5 | J10: =E10*0.12 -> 1152 | K10: =J10*I10 -> 5760
A11: Network | B11: Dell N1148T-ON (48x 1GbE) - OOB Management | C11: 4 | D11: 1950 | E11: =C11*D11 -> 7800 | F11: 0.23 | G11: =E11*F11 -> 1794 | H11: =E11+G11 -> 9594 | I11: 5 | J11: =E11*0.12 -> 936 | K11: =J11*I11 -> 4680
A12: SAN Fabric | B12: Brocade G720 (48-port 32Gb Fibre Channel Switch) | C12: 4 | D12: 24000 | E12: =C12*D12 -> 96000 | F12: 0.23 | G12: =E12*F12 -> 22080 | H12: =E12+G12 -> 118080 | I12: 5 | J12: =E12*0.15 -> 14400 | K12: =J12*I12 -> 72000
A13: SAN Fabric | B13: Emulex LPe36002-M2 (Dual-Port 32Gb FC HBA) | C13: 124 | D13: 850 | E13: =C13*D13 -> 105400 | F13: 0.23 | G13: =E13*F13 -> 24242 | H13: =E13+G13 -> 129642 | I13: 3 | J13: =E13*0.1 -> 10540 | K13: =J13*I13 -> 31620
A14: Infrastructure | B14: 42U Server Rack (Dell AR3100) with Dual PDU | C14: 13 | D14: 3200 | E14: =C14*D14 -> 41600 | F14: 0.23 | G14: =E14*F14 -> 9568 | H14: =E14+G14 -> 51168 | I14: 0 | J14: 0 | K14: =J14*I14 -> 0
A15: Infrastructure | B15: APC Smart-UPS SRT 10kVA (per rack pair) | C15: 7 | D15: 8500 | E15: =C15*D15 -> 59500 | F15: 0.23 | G15: =E15*F15 -> 13685 | H15: =E15+G15 -> 73185 | I15: 5 | J15: =E15*0.12 -> 7140 | K15: =J15*I15 -> 35700
A16: Infrastructure | B16: In-Row Cooling Unit (30kW) | C16: 4 | D16: 12000 | E16: =C16*D16 -> 48000 | F16: 0.23 | G16: =E16*F16 -> 11040 | H16: =E16+G16 -> 59040 | I16: 5 | J16: =E16*0.15 -> 7200 | K16: =J16*I16 -> 36000
A17: Cabling | B17: 25GbE SFP28 DAC Cable (3m) | C17: 240 | D17: 85 | E17: =C17*D17 -> 20400 | F17: 0.23 | G17: =E17*F17 -> 4692 | H17: =E17+G17 -> 25092 | I17: 0 | J17: 0 | K17: =J17*I17 -> 0
A18: Cabling | B18: 32Gb FC LC-LC OM4 Patch Cable (5m) | C18: 248 | D18: 45 | E18: =C18*D18 -> 11160 | F18: 0.23 | G18: =E18*F18 -> 2566.8 | H18: =E18+G18 -> 13726.8 | I18: 0 | J18: 0 | K18: =J18*I18 -> 0
A19: Cabling | B19: Cat6A Patch Cable (3m) | C19: 200 | D19: 12 | E19: =C19*D19 -> 2400 | F19: 0.23 | G19: =E19*F19 -> 552 | H19: =E19+G19 -> 2952 | I19: 0 | J19: 0 | K19: =J19*I19 -> 0
A20: HARDWARE SUBTOTAL | E20: =SUM(E5:E19) -> 3531660 | G20: =SUM(G5:G19) -> 812281.8 | H20: =SUM(H5:H19) -> 4343941.8 | J20: =SUM(J5:J19) -> 524848 | K20: =SUM(K5:K19) -> 2603160
A22: SOFTWARE / LICENSING
A23: Category | B23: Item | C23: Qty | D23: Net Unit Cost (EUR) | E23: Net Total (EUR) | F23: VAT Rate | G23: VAT Amount (EUR) | H23: Gross Total (EUR) | I23: Warranty (Yrs) | J23: Annual Warranty Cost (EUR) | K23: 5-Year Warranty Total (EUR)
A24: Virtualisation | B24: VMware vSphere Enterprise Plus (per CPU socket) | C24: 248 | D24: 6000 | E24: =C24*D24 -> 1488000 | F24: 0.23 | G24: =E24*F24 -> 342240 | H24: =E24+G24 -> 1830240 | I24: 5 | J24: =E24*0.2 -> 297600 | K24: =J24*I24 -> 1488000
A25: OS Licensing | B25: Windows Server 2022 Datacenter (per 2-socket server) | C25: 62 | D25: 7500 | E25: =C25*D25 -> 465000 | F25: 0.23 | G25: =E25*F25 -> 106950 | H25: =E25+G25 -> 571950 | I25: 0 | J25: 0 | K25: =J25*I25 -> 0
A26: Management | B26: VMware vCenter Server Standard | C26: 2 | D26: 8500 | E26: =C26*D26 -> 17000 | F26: 0.23 | G26: =E26*F26 -> 3910 | H26: =E26+G26 -> 20910 | I26: 5 | J26: =E26*0.2 -> 3400 | K26: =J26*I26 -> 17000
A27: Backup | B27: Veeam Backup and Replication Enterprise Plus (per socket) | C27: 248 | D27: 350 | E27: =C27*D27 -> 86800 | F27: 0.23 | G27: =E27*F27 -> 19964 | H27: =E27+G27 -> 106764 | I27: 1 | J27: =E27 -> 86800 | K27: =J27*I27 -> 86800
A28: Monitoring | B28: Dell OpenManage Enterprise Advanced (site licence) | C28: 1 | D28: 4500 | E28: =C28*D28 -> 4500 | F28: 0.23 | G28: =E28*F28 -> 1035 | H28: =E28+G28 -> 5535 | I28: 1 | J28: =E28 -> 4500 | K28: =J28*I28 -> 4500
A29: SOFTWARE SUBTOTAL | E29: =SUM(E24:E28) -> 2061300 | G29: =SUM(G24:G28) -> 474099 | H29: =SUM(H24:H28) -> 2535399 | J29: =SUM(J24:J28) -> 392300 | K29: =SUM(K24:K28) -> 1596300
A31: LABOUR / PROFESSIONAL SERVICES
A32: Role | B32: Description | C32: Personnel | D32: Days | E32: Day Rate (EUR) | F32: Net Total (EUR) | G32: VAT Rate | H32: VAT Amount (EUR) | I32: Gross Total (EUR)
A33: Project Manager | B33: Overall DC1 build project management and coordination | C33: 1 | D33: 120 | E33: 750 | F33: =C33*D33*E33 -> 90000 | G33: 0.23 | H33: =F33*G33 -> 20700 | I33: =F33+H33 -> 110700
A34: Solutions Architect | B34: Infrastructure design, HLD/LLD documentation, validation | C34: 1 | D34: 60 | E34: 950 | F34: =C34*D34*E34 -> 57000 | G34: 0.23 | H34: =F34*G34 -> 13110 | I34: =F34+H34 -> 70110
A35: Senior Systems Engineer | B35: Server rack and stack, firmware, BIOS/iDRAC config | C35: 2 | D35: 45 | E35: 650 | F35: =C35*D35*E35 -> 58500 | G35: 0.23 | H35: =F35*G35 -> 13455 | I35: =F35+H35 -> 71955
A36: Virtualisation Engineer | B36: VMware vSphere cluster build, vCenter, HA/DRS config | C36: 2 | D36: 40 | E36: 700 | F36: =C36*D36*E36 -> 56000 | G36: 0.23 | H36: =F36*G36 -> 12880 | I36: =F36+H36 -> 68880
A37: Storage Engineer | B37: PowerStore deployment, zoning, replication, SAN fabric | C37: 1 | D37: 35 | E37: 750 | F37: =C37*D37*E37 -> 26250 | G37: 0.23 | H37: =F37*G37 -> 6037.5 | I37: =F37+H37 -> 32287.5
A38: Network Engineer | B38: Spine-leaf fabric, VLAN, BGP/OSPF, firewall rules | C38: 2 | D38: 40 | E38: 700 | F38: =C38*D38*E38 -> 56000 | G38: 0.23 | H38: =F38*G38 -> 12880 | I38: =F38+H38 -> 68880
A39: AD / Identity Engineer | B39: Active Directory forest, 60-site RODC, DFS-R, GPO | C39: 1 | D39: 30 | E39: 650 | F39: =C39*D39*E39 -> 19500 | G39: 0.23 | H39: =F39*G39 -> 4485 | I39: =F39+H39 -> 23985
A40: Security Engineer | B40: Hardening, firewall policy, certificate services, audit | C40: 1 | D40: 25 | E40: 700 | F40: =C40*D40*E40 -> 17500 | G40: 0.23 | H40: =F40*G40 -> 4025 | I40: =F40+H40 -> 21525
A41: Backup Engineer | B41: Veeam deployment, backup jobs, DR runbook, testing | C41: 1 | D41: 20 | E41: 600 | F41: =C41*D41*E41 -> 12000 | G41: 0.23 | H41: =F41*G41 -> 2760 | I41: =F41+H41 -> 14760
A42: Cabling Contractor | B42: Structured cabling (power, fibre, copper) - team of 4 | C42: 4 | D42: 15 | E42: 450 | F42: =C42*D42*E42 -> 27000 | G42: 0.23 | H42: =F42*G42 -> 6210 | I42: =F42+H42 -> 33210
...

Sheet Power and Rack
A1: Electric Petrol DC1 - Power and Rack Summary
A3: POWER PARAMETERS
A4: Component | B4: Quantity | C4: Power/Unit (W) | D4: Total Power (kW)
A5: Compute Servers (R760) | B5: ='VM and Cluster Sizing'!B31 -> 120 | C5: 750 | D5: =B5*C5/1000 -> 90 | E5: Dell R760 typical: 750W avg (2x1400W PSU, Platinum 96% eff)
A6: Management Servers (R660) | B6: 4 | C6: 350 | D6: =B6*C6/1000 -> 1.4 | E6: Dell R660 typical: 350W avg (2x800W PSU)
A7: Storage Arrays + Shelves | B7: ='Storage Sizing'!B6 -> 2 | C7: 2200 | D7: =B7*C7/1000 -> 4.4 | E7: PowerStore 5200T: ~2.2kW per array with drives
A8: Network Switches | B8: 24 | C8: 180 | D8: =B8*C8/1000 -> 4.32 | E8: Dell S5248F-ON: 180W typical
A9: IT Load Subtotal (kW) | D9: =SUM(D5:D8) -> 100.12
A10: Overhead Factor | B10: 1.2 | C10: 20% for losses, cooling fans etc.
A11: TOTAL POWER (kW) | D11: =D9*B10 -> 120.144
A13: Cooling Required (tons) | C13: 1 ton = 3.517 kW | D13: =D11/3.517 -> 34.160933
A15: RACK SUMMARY
A16: Compute Racks (20 servers/rack, 2U each) | B16: 6
A17: Management Rack | B17: 1
A18: Storage Racks | B18: 2
A19: Network Racks | B19: 2
A20: TOTAL RACKS | B20: =SUM(B16:B19) -> 11
A22: Floor Space per Rack (sq m) | B22: 3.5 | C22: Including aisle space
A23: TOTAL FLOOR SPACE (sq m) | B23: =B20*B22 -> 38.5

Sheet Product Catalogue
A1: Electric Petrol DC1 - Product Catalogue (Ireland Pricing)
A2: All prices EUR ex-VAT. Source: dell.com/en-ie, broadcom.com, intel.com (May 2026)
A4: Product | B4: Model / Part Number | C4: Key Specifications | D4: Unit Price (EUR) | E4: Source Website
A5: COMPUTE SERVERS
A6: Rack Server (Compute) | B6: Dell PowerEdge R760 | C6: 2U | 2x Intel Xeon Gold 6430 (32-core, 2.1GHz) | 512GB DDR5-4800 (16x32GB RDIMM) | 32 DIMM slots max | 2x 480GB SSD M.2 BOSS-N1 (boot RAID1) | 6x 1.92TB NVMe U.2 SSD (data) | 2x 25GbE SFP28 onboard | 2x 25GbE SFP28 PCI-e | 1x 32Gb FC HBA | 2x 1400W Platinum PSU | iDRAC9 Enterprise | PERC H965i RAID | D6: 18500 | E6: dell.com/en-ie
A7: Rack Server (Management) | B7: Dell PowerEdge R660 | C7: 1U | 1x Intel Xeon Silver 4416+ (20-core, 2.0GHz) | 128GB DDR5-4800 (4x32GB) | 16 DIMM slots max | 2x 960GB SSD SATA (RAID1) | 2x 25GbE SFP28 | 2x 800W Platinum PSU | iDRAC9 Enterprise | PERC H755 RAID | D7: 7200 | E7: dell.com/en-ie
A9: STORAGE
A10: All-Flash SAN Array | B10: Dell PowerStore 5200T | C10: Dual Active-Active controllers | Intel Xeon CPU per controller | 256GB total cache | 25x 2.5in NVMe/SAS bays | Up to 1.2M IOPS (8KB read) | <0.3ms latency | 4x 25GbE iSCSI or 4x 32Gb FC per controller | Inline dedup + compression (4:1 typical) | Async/sync replication | Snapshots, thin provisioning | D10: 145000 | E10: dell.com/en-ie
A11: Expansion Shelf | B11: Dell PowerStore Expansion | C11: 25x 3.84TB NVMe SSD (Samsung PM9A3) | 96TB raw per shelf | Hot-pluggable | SAS backend to base unit | Max 3 shelves per base | D11: 48000 | E11: dell.com/en-ie
A12: NVMe SSD (in expansion) | B12: Samsung PM9A3 3.84TB | C12: 3.84TB | U.2 2.5in | PCIe Gen4 x4 | 6,500 MB/s read, 3,500 MB/s write | 800K/180K IOPS | 1 DWPD 5yr | AES-256 encryption | D12: 420 | E12: samsung.com/semiconductor
A14: NETWORKING
A15: Spine/Leaf Switch (25GbE) | B15: Dell S5248F-ON | C15: 48x 25GbE SFP28 + 6x 100GbE QSFP28 | OS10 Enterprise | L2/L3 | BGP/OSPF/VXLAN | 3.6 Tbps switching capacity | 1U | D15: 11500 | E15: dell.com/en-ie
A16: WAN/Edge Router | B16: Dell N3248TE-ON | C16: 48x 1GbE RJ45 + 4x 10GbE SFP+ | OS10 Enterprise | L3 routing | ACL/QoS | 176 Gbps switching | 1U | D16: 4800 | E16: dell.com/en-ie
A17: OOB Management Switch | B17: Dell N1148T-ON | C17: 48x 1GbE RJ45 + 4x 10GbE SFP+ | OS10 Lite | L2 switching | SNMP/SSH | 1U | D17: 1950 | E17: dell.com/en-ie
A19: SAN FABRIC
A20: FC Switch | B20: Broadcom Brocade G720 | C20: 48-port 32Gb Fibre Channel | 24 ports active (scalable to 48) | 768 Gbps aggregate | Low latency 0.7us | Fabric Vision | 1U | D20: 24000 | E20: broadcom.com
A21: FC Host Bus Adapter | B21: Broadcom Emulex LPe36002-M2 | C21: 32Gb FC Dual-Port | PCIe 4.0 x8 | Low Profile | 3.2M IOPS | Linux/Windows/ESXi drivers | Multipath support | D21: 850 | E21: broadcom.com
A23: INFRASTRUCTURE
A24: Server Rack | B24: Dell AR3100 42U | C24: 42U | 600mm W x 1200mm D | 1500kg static load | Split rear doors | 2x PDU vertical mount | Cable management | Perforated doors (front/rear) | D24: 3200 | E24: dell.com/en-ie
A26: PROCESSORS (included in server price)
A27: Server CPU (Compute) | B27: Intel Xeon Gold 6430 | C27: 32 cores / 64 threads | 2.1GHz base / 3.4GHz turbo | 270W TDP | 60MB L3 cache | DDR5-4800 8-channel | PCIe 5.0 | Socket 4677 (LGA) | D27: 2700 | E27: intel.com/ark
A28: Server CPU (Management) | B28: Intel Xeon Silver 4416+ | C28: 20 cores / 40 threads | 2.0GHz base / 3.9GHz turbo | 150W TDP | 37.5MB L3 cache | DDR5-4800 8-channel | Socket 4677 | D28: 1100 | E28: intel.com/ark
